<?xml version="1.0" ?>
<sdf version="1.7">
    
    <sdf:arg name="prefix" default="r"/>
    <prefix>prefix</prefix>
    <sdf:property name= "prefix" value="$(arg prefix)"/>
    <!-- <sdf:include filename="$(find robotont_description)/urdf/rim.urdf.xacro"/> -->
    <sdf:property name="wheel_distance" value="0.146"/>
    <sdf:property name="wheel_center_height" value="0.021"/>

    <world name="Moving_robot">
        <physics name="1ms" type="ignored">
            <max_step_size>0.001</max_step_size>
            <real_time_factor>1.0</real_time_factor>
        </physics>
        <plugin
            filename="libignition-gazebo-physics-system.so"
            name="ignition::gazebo::systems::Physics">
        </plugin>
        <plugin
            filename="libignition-gazebo-user-commands-system.so"
            name="ignition::gazebo::systems::UserCommands">
        </plugin>
        <plugin
            filename="libignition-gazebo-scene-broadcaster-system.so"
            name="ignition::gazebo::systems::SceneBroadcaster">
        </plugin>
        <plugin
            filename="ignition-gazebo-sensors-system"
            name="ignition::gazebo::systems::Sensors">
            <render_engine>ogre2</render_engine>
        </plugin>

        <gui fullscreen="0">

            <!-- 3D scene -->
            <plugin filename="GzScene3D" name="3D View">
                <ignition-gui>
                <title>3D View</title>
                <property type="bool" key="showTitleBar">false</property>
                <property type="string" key="state">docked</property>
                </ignition-gui>

                <engine>ogre2</engine>
                <scene>scene</scene>
                <ambient_light>0.4 0.4 0.4</ambient_light>
                <background_color>0.8 0.8 0.8</background_color>
                <camera_pose>-6 0 6 0 0.5 0</camera_pose>
            </plugin>

            <!-- World control -->
            <plugin filename="WorldControl" name="World control">
                <ignition-gui>
                <title>World control</title>
                <property type="bool" key="showTitleBar">false</property>
                <property type="bool" key="resizable">false</property>
                <property type="double" key="height">72</property>
                <property type="double" key="width">121</property>
                <property type="double" key="z">1</property>

                <property type="string" key="state">floating</property>
                <anchors target="3D View">
                    <line own="left" target="left"/>
                    <line own="bottom" target="bottom"/>
                </anchors>
                </ignition-gui>

                <play_pause>true</play_pause>
                <step>true</step>
                <start_paused>true</start_paused>
                <service>/world/Moving_robot/control</service>
                <stats_topic>/world/Moving_robot/stats</stats_topic>
            </plugin>

            <!-- World statistics -->
            <plugin filename="WorldStats" name="World stats">
                <ignition-gui>
                <title>World stats</title>
                <property type="bool" key="showTitleBar">false</property>
                <property type="bool" key="resizable">false</property>
                <property type="double" key="height">110</property>
                <property type="double" key="width">290</property>
                <property type="double" key="z">1</property>

                <property type="string" key="state">floating</property>
                <anchors target="3D View">
                    <line own="right" target="right"/>
                    <line own="bottom" target="bottom"/>
                </anchors>
                </ignition-gui>

                <sim_time>true</sim_time>
                <real_time>true</real_time>
                <real_time_factor>true</real_time_factor>
                <iterations>true</iterations>
                <topic>/world/Moving_robot/stats</topic>

            </plugin>

            <!-- Entity tree -->
            <plugin filename="EntityTree" name="Entity tree">
            </plugin>

            <!-- Entity tree -->
            <plugin filename="ComponentInspector" name="Component inspector">
            </plugin>

            <!-- KeyPublisher plugin-->
            <plugin filename="KeyPublisher" name="Key publisher"/>

            <plugin filename="ImageDisplay" name="Image display"/>
            
        </gui>

        <light type="directional" name="sun">
            <cast_shadows>true</cast_shadows>
            <pose>0 0 10 0 0 0</pose>
            <diffuse>0.8 0.8 0.8 1</diffuse>
            <specular>0.2 0.2 0.2 1</specular>
            <attenuation>
                <range>1000</range>
                <constant>0.9</constant>
                <linear>0.01</linear>
                <quadratic>0.001</quadratic>
            </attenuation>
            <direction>-0.5 0.1 -0.9</direction>
        </light>

        <model name="ground_plane">
            <static>true</static>
            <link name="link">
                <collision name="collision">
                <geometry>
                    <plane>
                    <normal>0 0 1</normal>
                    </plane>
                </geometry>
                </collision>
                <visual name="visual">
                <geometry>
                    <plane>
                    <normal>0 0 1</normal>
                    <size>100 100</size>
                    </plane>
                </geometry>
                <material>
                    <ambient>0.8 0.8 0.8 1</ambient>
                    <diffuse>0.8 0.8 0.8 1</diffuse>
                    <specular>0.8 0.8 0.8 1</specular>
                </material>
                </visual>
            </link>
        </model>

        <model name='robotont' canonical_link='base_footprint'>
            <pose relative_to=world> 0 0 0 0 0 0</pose>   <!--the pose is relative to the world by default-->
            
            <link name="base_footprint"/>

            <link name="base_link">
                <pose relative_to="base_footprint">0 0 0.013 0 0 1.57</pose>
                <!-- <pose relative_to="base_footprint">0 0 0 0 0 1.5707</pose> -->
                <visual name='visual'>
                    <geometry>
                        <mesh>
                            <scale>0.001 0.001 0.001</scale>
                            <uri> file://src/robotont_description/meshes/body.stl
                            </uri>
                        </mesh>
                    </geometry>
                    <material>
                        <!-- <color rgba="1 1 1 0.8"/> -->
                        <ambient>1 1 1 0.8</ambient>
                        <diffuse>1 1 1 0.8</diffuse>
                        <specular>1 1 1 0.8</specular>                         
                    </material>
                    <!-- <origin rpy="0 0 ${pi/2}"  xyz="0 0 0"/> -->
                    <origin>0 0 0 0 0 0</origin>
                </visual>
                <collision name='collision'>
                    <geometry>
                        <mesh>
                            <scale>0.001 0.001 0.001</scale>
                            <uri> file://src/robotont_description/meshes/simplebody.stl
                            </uri>
                        </mesh>
                    </geometry>
                    <origin>0 0 0 1.57 0 1.57</origin>
                </collision>
                <inertial>
                    <mass>3</mass>
                    <inertia>
                        <ixx>0.02462503</ixx>
                        <ixy>0</ixy>
                        <ixz>0</ixz>
                        <iyy>0.02082228</iyy>
                        <iyz>0</iyz>
                        <izz>0.04324237</izz>                        
                    </inertia>
                </inertial>
            </link>

            <joint name='base_joint' type='fixed'>
                <!-- <pose>0 0 0.013 0 0 0</pose> -->
                <parent>base_footprint</parent>
                <child>base_link</child>                         
            </joint>

            <!-- ===================================================== -->

            <include>
                <name>back</name>
                <pose relative_to="base_link">0 0.146 0.021 1.57 0 6.2831</pose>                
                <uri>
                model://rim
                </uri>                
            </include>

            <joint name="rim_back_joint" type="revolute">
                <pose relative_to='back::rim_link'/>
                <parent>base_link</parent>
                <child>back::rim_link</child>   
                <axis>
                    <xyz>0 0 1</xyz>
                    <limit>
                        <lower>-1.79769e+308</lower>    
                        <upper>1.79769e+308</upper>    
                    </limit>
                </axis>                                 
            </joint>

            <include>
                <name>right</name>
                <pose relative_to="base_link">-0.126439709 -0.073 0.021 1.57 0 2.094395102</pose>
                <uri>
                model://rim 
                </uri>
            </include>

            <joint name="rim_right_joint" type="revolute">
            <pose relative_to='right::rim_link'/>
                <parent>base_link</parent>
                <child>right::rim_link</child>   
                <axis>
                    <xyz>0 0 1</xyz>
                    <limit>
                        <lower>-1.79769e+308</lower>   
                        <upper>1.79769e+308</upper>    
                    </limit>
                </axis>                                 
            </joint>

            <include>
                <name>left</name>
                <pose relative_to="base_link">0.126439709 -0.073 0.021 1.57 0 4.188790205</pose>                
                <uri>
                model://rim 
                </uri>
            </include>

            <joint name="rim_left_joint" type="revolute">
            <pose relative_to='left::rim_link'/>
                <parent>base_link</parent>
                <child>left::rim_link</child>   
                <axis>
                    <xyz>0 0 1</xyz>
                    <limit>
                        <lower>-1.79769e+308</lower>   
                        <upper>1.79769e+308</upper>    
                    </limit>
                </axis>                                 
            </joint>

            <link name="camera_assembly_link1">
            <pose relative_to='base_link'>0 0 0.0125 0 0 0</pose>
                <visual name='visual'>
                    <geometry>
                        <mesh>
                            <scale>0.001 0.001 0.001</scale>
                            <uri> file://src/robotont_nuc_description/meshes/camera_assembly_part1.stl
                            </uri>
                        </mesh>
                    </geometry>
                    <material>
                        <ambient>1 1 1 1</ambient>
                        <diffuse>1 1 1 1</diffuse>
                        <specular>1 1 1 1</specular>                         
                    </material>                   
                </visual>
            </link>            
            <joint name="camera_assembly_joint1" type="fixed">
                <parent>base_footprint</parent>
                <child>camera_assembly_link1</child>
            </joint>

            <link name="camera_assembly_link2">
                <pose relative_to='base_link'>0 0 0.0125 0 0 0</pose>
                <visual name='visual'>
                    <geometry>
                        <mesh>
                            <scale>0.001 0.001 0.001</scale>
                            <uri> file://src/robotont_nuc_description/meshes/camera_assembly_part2.stl
                            </uri>
                        </mesh>
                    </geometry>
                    <material>
                        <ambient>1 1 1 0.8</ambient>
                        <diffuse>1 1 1 0.8</diffuse>
                        <specular>1 1 1 0.8</specular>   
                    </material>
                </visual>
            </link>
            <joint name="camera_assembly_joint2" type="fixed">                
                <parent>base_footprint</parent>
                <child>camera_assembly_link2</child>
            </joint>

            
            <!-- =====================Depth Camera ================================ -->

            <link name="depth_camera">
                <pose relative_to="base_link">0 0.115 0.2025 0 0.0 -1.57</pose>                
                <inertial>
                <mass>0.1</mass>
                <inertia>
                    <ixx>0.000166667</ixx>
                    <iyy>0.000166667</iyy>
                    <izz>0.000166667</izz>
                </inertia>
                </inertial>
                <collision name="collision">
                <geometry>
                    <!-- <mesh>
                        <scale>0.001 0.001 0.001</scale>
                        <uri> file://meshes/d435.dae
                        </uri>
                    </mesh> -->
                    <box>
                    <size>0.02 0.1 0.02</size>
                    </box>
                </geometry>
                </collision>
                <visual name="visual">
                <geometry>
                    <!-- <mesh>
                        <scale>0.001 0.001 0.001</scale>
                        <uri> file://meshes/d435.dae
                        </uri>
                    </mesh> -->
                    <box>
                    <size>0.02 0.1 0.02</size>
                    </box>
                </geometry>
                </visual>
                <sensor name="depth_camera1" type="depth_camera">
                    <update_rate>10</update_rate>
                    <topic>depth_camera</topic>
                    <camera>
                        <horizontal_fov>1.05</horizontal_fov>
                        <image>
                        <width>256</width>
                        <height>256</height>
                        <format>R_FLOAT32</format>
                        </image>
                        <clip>
                        <near>0.1</near>
                        <far>10.0</far>
                        </clip>
                    </camera>
                </sensor>
            </link>

            <joint name='camera_base_joint' type='fixed'>
                <pose>0 0.12 0.22 0 0.0 -1.57</pose>
                <parent>base_link</parent>
                <child>depth_camera</child>                         
            </joint>

            Computer
            <link name="computer_link">
                 <pose relative_to='base_link'>-0.01 0 0.085 0 0 0</pose>
                <visual name="visual">
                    <geometry>
                        <box>
                            <size>0.11 0.11 0.04</size>
                        </box>
                    </geometry>
                    <origin rpy="0 0 0" xyz="0 0 0"/>
                    <material>
                        <ambient>0.1 0.1 0.1 1</ambient>
                        <diffuse>0.1 0.1 0.1 1</diffuse>
                        <specular>0.1 0.1 0.1 1</specular>   
                    </material>
                </visual>
                <collision name="collision">
                    <geometry>
                        <box>
                            <size>0.11 0.11 0.04</size>
                        </box>
                    </geometry>
                    <origin>0 0 0 0 0 0</origin>
                </collision>
            </link>
            <joint name='computer_joint' type='fixed'>
                <parent>base_link</parent>
                <child>computer_link</child>                         
            </joint>
            


            <plugin
                filename="ignition-gazebo-velocity-control-system"
                name="ignition::gazebo::systems::VelocityControl">
            </plugin>

            <!-- Moving Forward-->
            <plugin filename="libignition-gazebo-triggered-publisher-system.so"
                    name="ignition::gazebo::systems::TriggeredPublisher">
                <input type="ignition.msgs.Int32" topic="/keyboard/keypress">
                    <match field="data">16777235</match>
                </input>
                <output type="ignition.msgs.Twist" topic="/model/robotont/cmd_vel">
                    linear: {x: 1}, angular: {z: 0.0}
                </output>
            </plugin>

            <!-- Moving Backward-->
            <plugin filename="libignition-gazebo-triggered-publisher-system.so"
                    name="ignition::gazebo::systems::TriggeredPublisher">
                <input type="ignition.msgs.Int32" topic="/keyboard/keypress">
                    <match field="data">16777237</match>
                </input>
                <output type="ignition.msgs.Twist" topic="/model/robotont/cmd_vel">
                    linear: {x: -1}, angular: {z: 0.0}
                </output>
            </plugin>

            <!-- Rotating right-->
            <plugin filename="libignition-gazebo-triggered-publisher-system.so"
                    name="ignition::gazebo::systems::TriggeredPublisher">
                <input type="ignition.msgs.Int32" topic="/keyboard/keypress">
                    <match field="data">16777236</match>
                </input>
                <output type="ignition.msgs.Twist" topic="/model/robotont/cmd_vel">
                    linear: {x: 0.0}, angular: {z: -1}
                </output>
            </plugin>

            <!--Rotating left-->
            <plugin filename="libignition-gazebo-triggered-publisher-system.so"
                    name="ignition::gazebo::systems::TriggeredPublisher">
                <input type="ignition.msgs.Int32" topic="/keyboard/keypress">
                    <match field="data">16777234</match>
                </input>
                <output type="ignition.msgs.Twist" topic="/model/robotont/cmd_vel">
                    linear: {x: 0.0}, angular: {z: 1}
                </output>
            </plugin>
        </model>

    
    </world>
</sdf>